I'm sorry, but an uncaught exception occurred.

After initialization, but before game start.
PermissionError: [WinError 32] The process cannot access the file because it is being used by another process: 'C:\\Users\\seven\\Downloads\\rnpy\\core\\game\\saves\\persistent'

-- Full Traceback ------------------------------------------------------------

Full traceback:
  File "C:\Users\seven\Downloads\renpy-8.3.6-sdk\renpy\bootstrap.py", line 359, in bootstrap
    renpy.main.main()
  File "C:\Users\seven\Downloads\renpy-8.3.6-sdk\renpy\main.py", line 666, in main
    renpy.persistent.update(True)
  File "C:\Users\seven\Downloads\renpy-8.3.6-sdk\renpy\persistent.py", line 434, in update
    save()
  File "C:\Users\seven\Downloads\renpy-8.3.6-sdk\renpy\persistent.py", line 456, in save
    renpy.loadsave.location.save_persistent(compressed)
  File "C:\Users\seven\Downloads\renpy-8.3.6-sdk\renpy\savelocation.py", line 622, in save_persistent
    l.save_persistent(data)
  File "C:\Users\seven\Downloads\renpy-8.3.6-sdk\renpy\savelocation.py", line 430, in save_persistent
    safe_rename(fn_new, fn)
  File "C:\Users\seven\Downloads\renpy-8.3.6-sdk\renpy\loadsave.py", line 303, in safe_rename
    os.unlink(new)
PermissionError: [WinError 32] The process cannot access the file because it is being used by another process: 'C:\\Users\\seven\\Downloads\\rnpy\\core\\game\\saves\\persistent'

Windows-10-10.0.26100 AMD64
Ren'Py 8.3.6.25022803
Aperture Dating Simulator 1.1.3.beta
Mon Aug 18 10:25:30 2025
